Workbook
Name Z_3F71F62A_D84C_452D_8D36_525BCD85F7AB_.wvu.PrintArea: 'G703'!$A$1:$J$36
Name Z_3F71F62A_D84C_452D_8D36_525BCD85F7AB_.wvu.PrintTitles: 'G703'!$1:$10
Name Z_74C40DAB_1E1B_4007_AE79_F07179D82744_.wvu.PrintArea: 'G703'!$A$1:$J$36
Name Z_74C40DAB_1E1B_4007_AE79_F07179D82744_.wvu.PrintTitles: 'G703'!$1:$10
Name Z_97571037_4E76_445A_98EC_9A5FE4082C32_.wvu.PrintArea: 'G703'!$A$1:$J$36
Name Z_97571037_4E76_445A_98EC_9A5FE4082C32_.wvu.PrintTitles: 'G703'!$1:$10
Name Z_BB6851ED_68DA_470F_99DD_B3BEA2AB9CAD_.wvu.PrintArea: 'G702'!$A$1:$H$46
Name Z_BB6851ED_68DA_470F_99DD_B3BEA2AB9CAD_.wvu.PrintArea: 'G703'!$A$1:$J$36
Name Z_BB6851ED_68DA_470F_99DD_B3BEA2AB9CAD_.wvu.PrintTitles: 'G703'!$1:$10
Name Z_CBA0EA1B_087A_4591_BC4D_CB2CC49841C4_.wvu.PrintArea: 'G703'!$A$1:$J$36
Name Z_CBA0EA1B_087A_4591_BC4D_CB2CC49841C4_.wvu.PrintTitles: 'G703'!$1:$10

Sheet G702
A1: APPLICATION AND CERTIFICATE FOR PAYMENT
A3: TO (Owner): | C3: PROJECT: | G3: APPLICATION NO:
G5: PERIOD FROM:
C6: G. C. : | G6: TO:
A7: FROM: | B7: BIG BEAR BUILDERS | G7: TERMS:
B8: P.O. BOX 770368
B9: MIAMI, FL 33177
A11: CONTRACTOR'S APPLICATION FOR PAYMENT
E12: The present status of the account for this Contract is as follows:
A13: CHANGE ORDER SUMMARY
A14: NUMBER | B14: ADDITIONS | C14: DEDUCTIONS | D14: 1. | E14: ORIGINAL CONTRACT SUM: | H14: ='G703'!C36 -> 0
A15: 1 | B15: ='G703'!C45 -> 0
B16: ='G703'!C46 -> 0 | D16: 2. | E16: Net Charge by Change Orders & Extras | H16: =SUM(B15:B42)-SUM(C15:C42) -> 0
B17: ='G703'!C47 -> 0
B18: ='G703'!C48 -> 0 | D18: 3. | E18: CONTRACT SUM TO DATE: | H18: =SUM(H14+H16) -> 0
B19: ='G703'!C49 -> 0
B20: ='G703'!C50 -> 0 | D20: 4. | E20: TOTAL COMPLETED & STORED TO DATE: | H20: ='G703'!G36+'G703'!G62 -> 0
B21: ='G703'!C51 -> 0
B22: ='G703'!C52 -> 0 | D22: 5. | E22: RETAINAGE FROM CURRENT BILLING | G22: 0.1 | H22: ='G703'!J36+'G703'!J62 -> 0
B23: ='G703'!C53 -> 0
B24: ='G703'!C54 -> 0 | D24: 6. | E24: TOTAL EARNED LESS RETAINAGE: | H24: ='G703'!G63-'G703'!J63 -> 0
B25: ='G703'!C55 -> 0
B26: ='G703'!C56 -> 0 | D26: 7. | E26: LESS PREVIOUS CERTIFICATES FOR PAYMENT: | H26: ='G703'!D63-('G703'!D63*'G702'!G22) -> 0
B27: ='G703'!C57 -> 0 | E27: (Line 6 from previous application)
B28: ='G703'!C58 -> 0 | D28: 8. | E28: CURRENT PAYMENT DUE: | H28: =H24-H26 -> 0
B29: ='G703'!C59 -> 0
B30: ='G703'!C60 -> 0
B31: ='G703'!C61 -> 0
B32: ='G703'!C62 -> 0
B33: ='G703'!C63 -> 0
B34: ='G703'!C64 -> 0
B35: ='G703'!C65 -> 0
B36: ='G703'!C66 -> 0
B37: ='G703'!C67 -> 0
B38: ='G703'!C68 -> 0
B39: ='G703'!C69 -> 0
B40: ='G703'!C70 -> 0
... B42: ='G703'!C72 -> 0
A43: TOTALS | B43: =SUM(B15:B42) -> 0 | C43: =SUM(C15:C26) -> 0 | D43: 9. | E43: BALANCE TO FINISH PLUS RETAINAGE | H43: ='G703'!I36+'G703'!J36+'G703'!I62+'G703'!J62 -> 0
E44: (Line 3 minus Line 6)
...

Sheet G703
A1: CONTINUATION SHEET | D1: AIA DOCUMENT G703
A2: BIG BEAR BUILDERS | C2: PROJECT: | D2: ='G702'!D3 -> 0
A3: P.O. BOX 770368 | C3: GC: | D3: ='G702'!D6 -> 0 | H3: Application #: | I3: ='G702'!H3 -> 0
A4: MIAMI, FL 33177 | D4: ='G702'!D7 -> 0 | H4: Period From: | I4: ='G702'!H5 -> 0
D5: ='G702'!D8 -> 0 | H5: Period To: | I5: ='G702'!H6 -> 0
A6: A | B6: C | C6: D | D6: E | E6: F | F6: G | G6: H | H6: I | I6: J | J6: K
A7: ITEM NO. | B7: DESCRIPTION OF WORK | C7: SCHEDULED VALUES | D7: WORK COMPLETED | F7: MATERIALS PRESENTLY STORED (NOT IN E OR F) | G7: TOTAL COMPLETED AND STORED TO DATE (E+F+G) | H7: % (H/D) | I7: BALANCE TO FINISH (D-H) | J7: RETAINAGE
D8: PREVIOUS APPLICATIONS (D + E) | E8: THIS PERIOD
A11: 1 | G11: =+D11+E11+F11 -> 0 | H11: =+G11/C11 -> #DIV/0! | I11: =+C11-G11 -> 0 | J11: =SUM(D11:E11)*'G702'!$G$22 -> 0
A12: =A11+1 -> 2 | G12: =+D12+E12+F12 -> 0 | H12: =+G12/C12 -> #DIV/0! | I12: =+C12-G12 -> 0 | J12: =SUM(G12)*'G702'!$G$22 -> 0
A13: =A12+1 -> 3 | G13: =+D13+E13+F13 -> 0 | H13: =+G13/C13 -> #DIV/0! | I13: =+C13-G13 -> 0 | J13: =SUM(G13)*'G702'!$G$22 -> 0
A14: =A13+1 -> 4 | G14: =+D14+E14+F14 -> 0 | H14: =+G14/C14 -> #DIV/0! | I14: =+C14-G14 -> 0 | J14: =SUM(G14)*'G702'!$G$22 -> 0
A15: =A14+1 -> 5 | G15: =+D15+E15+F15 -> 0 | H15: =+G15/C15 -> #DIV/0! | I15: =+C15-G15 -> 0 | J15: =SUM(G15)*'G702'!$G$22 -> 0
A16: =A15+1 -> 6 | G16: =+D16+E16+F16 -> 0 | H16: =+G16/C16 -> #DIV/0! | I16: =+C16-G16 -> 0 | J16: =SUM(G16)*'G702'!$G$22 -> 0
A17: =A16+1 -> 7 | G17: =+D17+E17+F17 -> 0 | H17: =+G17/C17 -> #DIV/0! | I17: =+C17-G17 -> 0 | J17: =SUM(G17)*'G702'!$G$22 -> 0
A18: =A17+1 -> 8 | G18: =+D18+E18+F18 -> 0 | H18: =+G18/C18 -> #DIV/0! | I18: =+C18-G18 -> 0 | J18: =SUM(G18)*'G702'!$G$22 -> 0
A19: =A18+1 -> 9 | G19: =+D19+E19+F19 -> 0 | H19: =+G19/C19 -> #DIV/0! | I19: =+C19-G19 -> 0 | J19: =SUM(G19)*'G702'!$G$22 -> 0
A20: =A19+1 -> 10 | G20: =+D20+E20+F20 -> 0 | H20: =+G20/C20 -> #DIV/0! | I20: =+C20-G20 -> 0 | J20: =SUM(G20)*'G702'!$G$22 -> 0
A21: =A20+1 -> 11 | G21: =+D21+E21+F21 -> 0 | H21: =+G21/C21 -> #DIV/0! | I21: =+C21-G21 -> 0 | J21: =SUM(D21:E21)*'G702'!$G$22 -> 0
A22: 12 | G22: =+D22+E22+F22 -> 0 | H22: =+G22/C22 -> #DIV/0! | I22: =+C22-G22 -> 0 | J22: =SUM(D22:E22)*'G702'!$G$22 -> 0
A23: 13 | G23: =+D23+E23+F23 -> 0 | H23: =+G23/C23 -> #DIV/0! | I23: =+C23-G23 -> 0 | J23: =SUM(D23:E23)*'G702'!$G$22 -> 0
A24: 14 | G24: =+D24+E24+F24 -> 0 | H24: =+G24/C24 -> #DIV/0! | I24: =+C24-G24 -> 0 | J24: =SUM(G24)*'G702'!$G$22 -> 0
A25: =A24+1 -> 15
A26: =A25+1 -> 16
A27: =A26+1 -> 17
A28: =A27+1 -> 18
A29: =A28+1 -> 19
A30: =A29+1 -> 20
A31: =A30+1 -> 21
A32: =A31+1 -> 22
A33: =A32+1 -> 23
A34: =A33+1 -> 24
A35: =A34+1 -> 25
B36: TOTALS | C36: =SUM(C11:C35) -> 0 | D36: =SUM(D11:D35) -> 0 | E36: =SUM(E11:E35) -> 0 | F36: =SUM(F11:F35) -> 0 | G36: =SUM(G11:G35) -> 0 | H36: =+G36/C36 -> #DIV/0! | I36: =SUM(I11:I35) -> 0 | J36: =SUM(J11:J35) -> 0
B39: Change Orders
A40: A | B40: C | C40: D | D40: E | E40: F | F40: G | G40: H | H40: I | I40: J | J40: K
A41: ITEM NO. | B41: DESCRIPTION OF WORK | C41: SCHEDULED VALUES | D41: WORK COMPLETED | F41: MATERIALS PRESENTLY STORED (NOT IN E OR F) | G41: TOTAL COMPLETED AND STORED TO DATE (E+F+G) | H41: % (H/D) | I41: BALANCE TO FINISH (D-H) | J41: RETAINAGE
D42: PREVIOUS APPLICATIONS (D + E) | E42: THIS PERIOD
A45: 1 | G45: =+D45+E45+F45 -> 0 | H45: =+G45/C45 -> #DIV/0! | I45: =+C45-G45 -> 0 | J45: =SUM(G45)*'G702'!$G$22 -> 0
A46: =A45+1 -> 2 | G46: =+D46+E46+F46 -> 0 | H46: =+G46/C46 -> #DIV/0! | I46: =+C46-G46 -> 0 | J46: =SUM(G46)*'G702'!$G$22 -> 0
...
